package fr.eql.ai108.exception;

public class Lanceur {

	
	//Ici l'exception s'est propagée jusqu'au main et n'a jamais été gérée. Du coup, le programme cette de s'exécuter
//	public static void main(String[] args) throws Exception {
//
//
//		Calculatrice calc = new Calculatrice();
//		
//		double result = calc.diviser(20, 0);
//		
//		System.out.println("____________________________________________________");
//		System.out.println(result);
//
//	}
	
	

	public static void main(String[] args) {


		Calculatrice calc = new Calculatrice();
		
		double result;
		//Essaye d'effectuer la division: try
		try {
			result = calc.diviser(20, 0);
		} catch (Exception e) {
			// TODO Auto-generated catch block
			e.printStackTrace();
		}
		
		System.out.println("____________________________________________________");
		System.out.println(result);

	}

}
